[2024-09-24 02:02:39,531] torch.distributed.run: [WARNING] master_addr is only used for static rdzv_backend and when rdzv_endpoint is not specified.
[rank: 2] Seed set to 77843
[rank: 0] Seed set to 77843
[rank: 1] Seed set to 77843
Traceback (most recent call last):
  File "/work/10110/abhinav22/ls6/openfold/train_openfold.py", line 766, in <module>
    main(args)
  File "/work/10110/abhinav22/ls6/openfold/train_openfold.py", line 366, in main
    sd = get_model_state_dict_from_ds_checkpoint(args.resume_from_ckpt)
  File "/work/10110/abhinav22/ls6/openfold/train_openfold.py", line 311, in get_model_state_dict_from_ds_checkpoint
    raise ValueError(f"Unable to find 'latest' file at {latest_path}")
ValueError: Unable to find 'latest' file at /scratch/10110/abhinav22/output_dir/openfold_training/uapyjamj/checkpoints/latest
Traceback (most recent call last):
  File "/work/10110/abhinav22/ls6/openfold/train_openfold.py", line 766, in <module>
    main(args)
  File "/work/10110/abhinav22/ls6/openfold/train_openfold.py", line 366, in main
    sd = get_model_state_dict_from_ds_checkpoint(args.resume_from_ckpt)
  File "/work/10110/abhinav22/ls6/openfold/train_openfold.py", line 311, in get_model_state_dict_from_ds_checkpoint
    raise ValueError(f"Unable to find 'latest' file at {latest_path}")
ValueError: Unable to find 'latest' file at /scratch/10110/abhinav22/output_dir/openfold_training/uapyjamj/checkpoints/latest
Traceback (most recent call last):
  File "/work/10110/abhinav22/ls6/openfold/train_openfold.py", line 766, in <module>
    main(args)
  File "/work/10110/abhinav22/ls6/openfold/train_openfold.py", line 366, in main
    sd = get_model_state_dict_from_ds_checkpoint(args.resume_from_ckpt)
  File "/work/10110/abhinav22/ls6/openfold/train_openfold.py", line 311, in get_model_state_dict_from_ds_checkpoint
    raise ValueError(f"Unable to find 'latest' file at {latest_path}")
ValueError: Unable to find 'latest' file at /scratch/10110/abhinav22/output_dir/openfold_training/uapyjamj/checkpoints/latest
[2024-09-24 02:04:09,985] torch.distributed.elastic.multiprocessing.api: [ERROR] failed (exitcode: 1) local_rank: 0 (pid: 673458) of binary: /work/10110/abhinav22/ls6/src/miniforge/envs/openfold_cuda12/bin/python
Traceback (most recent call last):
  File "/work/10110/abhinav22/ls6/src/miniforge/envs/openfold_cuda12/bin/torchrun", line 33, in <module>
    sys.exit(load_entry_point('torch==2.1.2', 'console_scripts', 'torchrun')())
  File "/work/10110/abhinav22/ls6/src/miniforge/envs/openfold_cuda12/lib/python3.10/site-packages/torch/distributed/elastic/multiprocessing/errors/__init__.py", line 346, in wrapper
    return f(*args, **kwargs)
  File "/work/10110/abhinav22/ls6/src/miniforge/envs/openfold_cuda12/lib/python3.10/site-packages/torch/distributed/run.py", line 806, in main
    run(args)
  File "/work/10110/abhinav22/ls6/src/miniforge/envs/openfold_cuda12/lib/python3.10/site-packages/torch/distributed/run.py", line 797, in run
    elastic_launch(
  File "/work/10110/abhinav22/ls6/src/miniforge/envs/openfold_cuda12/lib/python3.10/site-packages/torch/distributed/launcher/api.py", line 134, in __call__
    return launch_agent(self._config, self._entrypoint, list(args))
  File "/work/10110/abhinav22/ls6/src/miniforge/envs/openfold_cuda12/lib/python3.10/site-packages/torch/distributed/launcher/api.py", line 264, in launch_agent
    raise ChildFailedError(
torch.distributed.elastic.multiprocessing.errors.ChildFailedError: 
============================================================
train_openfold.py FAILED
------------------------------------------------------------
Failures:
[1]:
  time      : 2024-09-24_02:04:09
  host      : c305-004.ls6.tacc.utexas.edu
  rank      : 1 (local_rank: 1)
  exitcode  : 1 (pid: 673459)
  error_file: <N/A>
  traceback : To enable traceback see: https://pytorch.org/docs/stable/elastic/errors.html
[2]:
  time      : 2024-09-24_02:04:09
  host      : c305-004.ls6.tacc.utexas.edu
  rank      : 2 (local_rank: 2)
  exitcode  : 1 (pid: 673460)
  error_file: <N/A>
  traceback : To enable traceback see: https://pytorch.org/docs/stable/elastic/errors.html
------------------------------------------------------------
Root Cause (first observed failure):
[0]:
  time      : 2024-09-24_02:04:09
  host      : c305-004.ls6.tacc.utexas.edu
  rank      : 0 (local_rank: 0)
  exitcode  : 1 (pid: 673458)
  error_file: <N/A>
  traceback : To enable traceback see: https://pytorch.org/docs/stable/elastic/errors.html
============================================================
srun: error: c305-004: task 0: Exited with exit code 1
